# 에러처리
## 1. 에러처리의 필요성
발생한 에러에 대하여 대처하지 않으면 프로그램은 강제 종료된다. try...catch문을 사용해 에러에 적절히 대응하면 프로그램이 강제로 종료되지 않는다.

또 에러를 발생시키지 않는 예외적인 상황이 발생할 수도 있다. 이러한 예외 상황도 적절히 대응하지 않으면 에러로 이어질 수 있다.

## 2. try...catch...finally문

    try {
        // 실행할 코드(에러가 발생할 가능성이 있는 코드)
    }catch(err) {
        // try블록에서 에러 발생시 이 코드의 블록이 실행됨
    }finally {
        // error 발생과 상관없이 반드시 한 번 실행된다.
    }

## 3. Error 객체
Error 생성자 함수는 에러 객체를 생성한다. 에러 메세지를 인수로 전달할 수 있다.

에러 객체는 message 프로퍼티와 stack 프로퍼티를 갖는다. message 프로퍼티는 인수로 전달한 에러메시지이고, stack 프로퍼티는 에러를 발생시킨 콜 스택의 호출 정보를 나타내는 문자열이다.
* Error : 일반적인 에러객체
* SyntaxError : 문법에 맞지않는 문을 해석할때
* ReferenceError : 참조할 수 없는 식별자를 참조시
* TypeError : 피연산자 또는 인수의 데이터 타입이 유효하지 않을 때
* RangeError : 숫자값의 허용범위를 벗어났을 때
* URIError : encodeURI, decodeURI 함수에 부적절한 인수를 전달시
* EvalError : eval 함수에서 발생하는 에러 객체

## 4. throw문
try블록 안에서 throw문을 이용하여 에러를 던지면 catch문의 에러 변수가 생성되고 던져진 에러 객체가 할당된다. 그리고 catch블록이 실행된다.

    try{
        throw new Error('something wrong');
    }catch (error) {
        console.log(error);
    }

## 5. 에러의 전파

    const foo = () => {
        throw Error('foo에서 발생한 에러');  //4
    };

    const bar = () => {
        foo();  //3
    };

    const baz = () => {
        bar();  //2
    };

    try {
        baz();  //1
    }catch (err) {
        console.error(err);
    }

foo 실행 컨텍스트 -> bar 실행 컨텍스트 -> baz 실행 컨텍스트 -> 전역 실행 컨텍스트